Workbook

Sheet Project Inputs
A1: PROJECT INPUTS
A2: Complete this sheet first. Fields highlighted in blue/cream are editable inputs; all other sheets reference these values.
A4: PROJECT DETAILS
B5: Project Name | C5: The Grand Wedding Weekend
B6: Client Name | C6: Mr. & Mrs. Sharma
B7: Event Date | C7: 2026-11-14
B8: Venue | C8: The Leela Palace Lawns
B9: City | C9: Udaipur
B10: Event Type | C10: Wedding
B11: Estimated Pax | C11: 400
B12: Buffer % | C12: 0.08
B13: Costing Pax | C13: =C11*(1+C12) -> 432
B14: Number of Service Days | C14: 2
B15: Setup Date | C15: 2026-11-13
B16: Dismantle Date | C16: 2026-11-15
B17: Meal Periods | C17: Hi-Tea, Dinner
B18: Menu Type | C18: Veg + Non-Veg
B19: Service Style | C19: Buffet
B20: Prepared By | C20: Costing Team
B21: Version Number | C21: v1.0
B22: Date Prepared | C22: 2026-07-04
B23: Notes / Assumptions | C23: Standard buffet wedding package. Rates based on Rate Master as of July 2026. Alcohol excluded from bar costing.
A27: GLOBAL ASSUMPTIONS
B28: Default Wastage % | C28: 0.05
B29: Default Contingency % | C29: 0.03
B30: GST % | C30: 0.18
B31: Staff Meal Cost per Person | C31: 180
B32: Transportation Contingency % | C32: 0.05
B33: Default Working Hours per Shift | C33: 8
B34: Default Staff Shift Rate | C34: 1000
B35: Default Chef Shift Rate | C35: 3500

Sheet Estimate Summary
A1: ESTIMATE SUMMARY
A2: Management-facing roll-up of the base cost estimate. Profit is loaded separately below and never blended into the base cost figures.
A4: BASE COST ESTIMATE
B5: Cost Head | C5: Estimated Cost (₹) | D5: % of Total Cost | E5: Notes
B6: Service Cost | C6: =ServiceCostTotal -> 117820 | D6: =C6/$C$16 -> 0.15360237 | E6: Servers, butlers, captains, stewards & support staff
B7: Setup Cost | C7: =SetupCostTotal -> 225378 | D7: =C7/$C$16 -> 0.29382614 | E7: Crockery, cutlery, décor, furniture & setup manpower
B8: Food Cost | C8: =FoodCostTotal -> 38171.304 | D8: =C8/$C$16 -> 0.049764072 | E8: Ingredient-level costing across the full menu
B9: Coffee Cost | C9: =CoffeeCostTotal -> 50420 | D9: =C9/$C$16 -> 0.065732743 | E9: Coffee station consumables & barista service
B10: Cocktail & Mocktail Bar Cost | C10: =BarCostTotal -> 76780 | D10: =C10/$C$16 -> 0.10009837 | E10: Non-alcoholic bar program (alcohol excluded)
B11: Miscellaneous Expenses | C11: =MiscCostTotal -> 54500 | D11: =C11/$C$16 -> 0.071051854 | E11: Printing, packaging, petty cash & event-day sundries
B12: ODC Chef Cost | C12: =ChefCostTotal -> 117900 | D12: =C12/$C$16 -> 0.15370667 | E12: Off-site culinary team deployed to venue
B13: Transportation Cost | C13: =TransportCostTotal -> 63735 | D13: =C13/$C$16 -> 0.083091558 | E13: Vehicles, fuel, tolls & logistics manpower
B14: Subtotal (Before Contingency) | C14: =SUM(C6:C13) -> 744704.3
B15: Contingency | C15: =C14*DefaultContingencyPct -> 22341.129 | D15: =C15/$C$16 -> 0.029126214 | E15: Applied at Default Contingency % from Project Inputs
B16: TOTAL ESTIMATED BASE COST | C16: =C14+C15 -> 767045.43
B17: Estimated Cost per Pax | C17: =C16/CostingPax -> 1775.5681
A19: COMMERCIAL VIEW — PROFIT LOADING (SEPARATE FROM BASE COST)
B20: Profit Loading % | C20: 0.2
B21: Profit Amount | C21: =TotalEstimatedBaseCost*C20 -> 153409.09
B22: Final Commercial Before GST | C22: =TotalEstimatedBaseCost+C21 -> 920454.52
B23: GST Amount | C23: =C22*GSTPct -> 165681.81
B24: Final Commercial Including GST | C24: =C22+C23 -> 1086136.3

Sheet Service Cost
A1: SERVICE COST ESTIMATE
A2: Staffing plan for guest-facing and back-of-house service roles. Total Cost = (Staff x Shifts x Rate) + Staff Meal Cost + Conveyance.
A4: Role Category | B4: Role | C4: Description | D4: No. of Staff | E4: No. of Shifts / Days | F4: Hours per Shift | G4: Rate per Shift (₹) | H4: Staff Meal Required? | I4: Staff Meal Cost (₹) | J4: Conveyance / Allowance (₹) | K4: Total Cost (₹) | L4: Notes
A5: Front of House | B5: Service Captain | C5: Oversees service team, manages guest experience | D5: 2 | E5: =ServiceDays -> 2 | F5: 8 | G5: 2500 | H5: No | I5: =IF(H5="Yes",D5*E5*StaffMealCost,0) -> 0 | J5: 500 | K5: =D5*E5*G5+I5+J5 -> 10500
A6: Front of House | B6: Butler | C6: Dedicated guest butler service | D6: 4 | E6: =ServiceDays -> 2 | F6: 8 | G6: 2200 | H6: No | I6: =IF(H6="Yes",D6*E6*StaffMealCost,0) -> 0 | J6: 500 | K6: =D6*E6*G6+I6+J6 -> 18100
A7: Front of House | B7: Server | C7: Table / buffet service staff | D7: 10 | E7: =ServiceDays -> 2 | F7: 8 | G7: 1200 | H7: Yes | I7: =IF(H7="Yes",D7*E7*StaffMealCost,0) -> 3600 | J7: 300 | K7: =D7*E7*G7+I7+J7 -> 27900
A8: Support | B8: Support Staff | C8: General service support | D8: 6 | E8: =ServiceDays -> 2 | F8: 8 | G8: 1000 | H8: Yes | I8: =IF(H8="Yes",D8*E8*StaffMealCost,0) -> 2160 | J8: 200 | K8: =D8*E8*G8+I8+J8 -> 14360
A9: Support | B9: Steward | C9: Buffet & station stewarding | D9: 5 | E9: =ServiceDays -> 2 | F9: 8 | G9: 1100 | H9: Yes | I9: =IF(H9="Yes",D9*E9*StaffMealCost,0) -> 1800 | J9: 200 | K9: =D9*E9*G9+I9+J9 -> 13000
A10: Support | B10: Clearing Staff | C10: Table / buffet clearing | D10: 4 | E10: =ServiceDays -> 2 | F10: 8 | G10: 900 | H10: Yes | I10: =IF(H10="Yes",D10*E10*StaffMealCost,0) -> 1440 | J10: 150 | K10: =D10*E10*G10+I10+J10 -> 8790
A11: Support | B11: Washing Staff | C11: On-site washing support | D11: 3 | E11: =ServiceDays -> 2 | F11: 8 | G11: 900 | H11: Yes | I11: =IF(H11="Yes",D11*E11*StaffMealCost,0) -> 1080 | J11: 150 | K11: =D11*E11*G11+I11+J11 -> 6630
A12: Logistics | B12: Loader | C12: Loading / unloading support | D12: 3 | E12: =ServiceDays -> 2 | F12: 6 | G12: 900 | H12: No | I12: =IF(H12="Yes",D12*E12*StaffMealCost,0) -> 0 | J12: 200 | K12: =D12*E12*G12+I12+J12 -> 5600
A13: Logistics | B13: Runner | C13: Kitchen-to-service runner | D13: 4 | E13: =ServiceDays -> 2 | F13: 8 | G13: 900 | H13: Yes | I13: =IF(H13="Yes",D13*E13*StaffMealCost,0) -> 1440 | J13: 150 | K13: =D13*E13*G13+I13+J13 -> 8790
A14: Housekeeping | B14: Housekeeping | C14: Venue housekeeping support | D14: 2 | E14: =ServiceDays -> 2 | F14: 8 | G14: 1000 | H14: No | I14: =IF(H14="Yes",D14*E14*StaffMealCost,0) -> 0 | J14: 150 | K14: =D14*E14*G14+I14+J14 -> 4150
K15: =SUM(K5:K14) -> 117820

Sheet Setup Cost
A1: SETUP COST ESTIMATE
A2: Décor, equipment, crockery/cutlery and setup manpower. Total Cost = (Qty x Days x Unit Rate x (1 + Damage Buffer %)) + Setup / Handling Cost.
A4: Setup Category | B4: Item / Resource | C4: Description | D4: Quantity | E4: No. of Days | F4: Unit Rate (₹) | G4: Damage Buffer % | H4: Setup / Handling Cost (₹) | I4: Total Cost (₹) | J4: Vendor / Source | K4: Notes
A5: Crockery | B5: Crockery Set | C5: Plates, bowls, side plates per cover | D5: 420 | E5: 2 | F5: 45 | G5: 0.03 | H5: 1500 | I5: =D5*E5*F5*(1+G5)+H5 -> 40434 | J5: Elite Rentals
A6: Cutlery | B6: Cutlery Set | C6: Full cutlery set per cover | D6: 420 | E6: 2 | F6: 20 | G6: 0.03 | H6: 800 | I6: =D6*E6*F6*(1+G6)+H6 -> 18104 | J6: Elite Rentals
A7: Glassware | B7: Glassware Set | C7: Water / juice / cocktail glasses per cover | D7: 420 | E7: 2 | F7: 25 | G7: 0.05 | H7: 1000 | I7: =D7*E7*F7*(1+G7)+H7 -> 23050 | J7: Elite Rentals
A8: Serviceware | B8: Serving Platters & Bowls | C8: Buffet serving platters, bowls, tongs | D8: 60 | E8: 2 | F8: 60 | G8: 0.03 | H8: 500 | I8: =D8*E8*F8*(1+G8)+H8 -> 7916 | J8: Elite Rentals
A9: Buffet Counters | B9: Buffet Counter Units | C9: Modular buffet counters with skirting | D9: 8 | E9: 2 | F9: 1800 | G9: 0 | H9: 2000 | I9: =D9*E9*F9*(1+G9)+H9 -> 30800 | J9: Décor Partner
A10: Chafing Dishes | B10: Chafing Dish (Full Size) | C10: Hot food chafing dish with fuel | D10: 20 | E10: 2 | F10: 350 | G10: 0.02 | H10: 800 | I10: =D10*E10*F10*(1+G10)+H10 -> 15080 | J10: Elite Rentals
A11: Risers | B11: Buffet Risers & Stands | C11: Display risers for buffet elevation | D11: 15 | E11: 2 | F11: 250 | G11: 0.02 | H11: 300 | I11: =D11*E11*F11*(1+G11)+H11 -> 7950 | J11: Décor Partner
A12: Lamps | B12: Table / Ambient Lamps | C12: Decorative table and ambient lighting | D12: 25 | E12: 2 | F12: 150 | G12: 0.02 | H12: 400 | I12: =D12*E12*F12*(1+G12)+H12 -> 8050 | J12: Décor Partner
A13: Tables | B13: Round / Buffet Tables | C13: Guest round tables + buffet tables | D13: 45 | E13: 2 | F13: 300 | G13: 0 | H13: 1000 | I13: =D13*E13*F13*(1+G13)+H13 -> 28000 | J13: Elite Rentals
A14: Linen | B14: Table Linen & Overlays | C14: Table cloths, overlays, napkins | D14: 45 | E14: 2 | F14: 220 | G14: 0.03 | H14: 600 | I14: =D14*E14*F14*(1+G14)+H14 -> 20994 | J14: Linen House
A15: Setup Staff | B15: Setup Staff | C15: Setup and breakdown manpower | D15: 8 | E15: 2 | F15: 1000 | G15: 0 | H15: 0 | I15: =D15*E15*F15*(1+G15)+H15 -> 16000 | J15: In-house
A16: Washing / Clearing | B16: Washing / Clearing Staff | C16: On-site washing and clearing during setup | D16: 5 | E16: 2 | F16: 900 | G16: 0 | H16: 0 | I16: =D16*E16*F16*(1+G16)+H16 -> 9000 | J16: In-house
I17: =SUM(I5:I16) -> 225378

Sheet Food Cost
A1: FOOD COST ESTIMATE
A2: Ingredient-level costing by dish. Total Qty Required = Qty per Pax x Costing Pax. Total Ingredient Cost = Total Qty x Rate per Unit x (1 + Wastage %).
A4: Menu Section | B4: Dish Name | C4: Ingredient Category | D4: Ingredient Name | E4: Unit | F4: Quantity per Pax | G4: Costing Pax | H4: Total Quantity Required | I4: Rate per Unit (₹) | J4: Wastage % | K4: Total Ingredient Cost (₹) | L4: Notes
A5: Starters | B5: Paneer Tikka | C5: Dairy | D5: Paneer | E5: kg | F5: 0.08 | G5: =CostingPax -> 432 | H5: =F5*G5 -> 34.56 | I5: 380 | J5: 0.05 | K5: =H5*I5*(1+J5) -> 13789.44
A6: Starters | B6: Paneer Tikka | C6: Spices | D6: Tikka Masala Spice Mix | E6: kg | F6: 0.005 | G6: =CostingPax -> 432 | H6: =F6*G6 -> 2.16 | I6: 900 | J6: 0.05 | K6: =H6*I6*(1+J6) -> 2041.2
A7: Starters | B7: Paneer Tikka | C7: Vegetables | D7: Capsicum & Onion | E7: kg | F7: 0.03 | G7: =CostingPax -> 432 | H7: =F7*G7 -> 12.96 | I7: 60 | J7: 0.08 | K7: =H7*I7*(1+J7) -> 839.808
A8: Main Course | B8: Dal Makhani | C8: Dry Stock | D8: Black Lentils (Urad Dal) | E8: kg | F8: 0.05 | G8: =CostingPax -> 432 | H8: =F8*G8 -> 21.6 | I8: 180 | J8: 0.03 | K8: =H8*I8*(1+J8) -> 4004.64
A9: Main Course | B9: Dal Makhani | C9: Dairy | D9: Butter & Cream | E9: kg | F9: 0.02 | G9: =CostingPax -> 432 | H9: =F9*G9 -> 8.64 | I9: 450 | J9: 0.03 | K9: =H9*I9*(1+J9) -> 4004.64
A10: Main Course | B10: Dal Makhani | C10: Spices | D10: Whole & Ground Spices | E10: kg | F10: 0.004 | G10: =CostingPax -> 432 | H10: =F10*G10 -> 1.728 | I10: 700 | J10: 0.05 | K10: =H10*I10*(1+J10) -> 1270.08
A11: Breads | B11: Butter Naan | C11: Bakery | D11: Refined Flour (Maida) | E11: kg | F11: 0.07 | G11: =CostingPax -> 432 | H11: =F11*G11 -> 30.24 | I11: 45 | J11: 0.03 | K11: =H11*I11*(1+J11) -> 1401.624
A12: Breads | B12: Butter Naan | C12: Dairy | D12: Butter | E12: kg | F12: 0.01 | G12: =CostingPax -> 432 | H12: =F12*G12 -> 4.32 | I12: 480 | J12: 0.03 | K12: =H12*I12*(1+J12) -> 2135.808
A13: Breads | B13: Butter Naan | C13: Other | D13: Tandoor Fuel Allocation | E13: unit | F13: 0.01 | G13: =CostingPax -> 432 | H13: =F13*G13 -> 4.32 | I13: 200 | J13: 0 | K13: =H13*I13*(1+J13) -> 864
A14: Desserts | B14: Gulab Jamun | C14: Dairy | D14: Khoya | E14: kg | F14: 0.04 | G14: =CostingPax -> 432 | H14: =F14*G14 -> 17.28 | I14: 380 | J14: 0.05 | K14: =H14*I14*(1+J14) -> 6894.72
A15: Desserts | B15: Gulab Jamun | C15: Dry Stock | D15: Sugar | E15: kg | F15: 0.03 | G15: =CostingPax -> 432 | H15: =F15*G15 -> 12.96 | I15: 55 | J15: 0.02 | K15: =H15*I15*(1+J15) -> 727.056
A16: Desserts | B16: Gulab Jamun | C16: Bakery | D16: Refined Flour | E16: kg | F16: 0.01 | G16: =CostingPax -> 432 | H16: =F16*G16 -> 4.32 | I16: 45 | J16: 0.02 | K16: =H16*I16*(1+J16) -> 198.288
K17: =SUM(K5:K16) -> 38171.304
A19: DISH-WISE SUMMARY
A20: Dish Name | B20: Total Dish Cost (₹) | C20: Cost per Pax (₹)
A21: Paneer Tikka | B21: =SUMIF($B$5:$B$16,A21,$K$5:$K$16) -> 16670.448 | C21: =B21/CostingPax -> 38.589
A22: Dal Makhani | B22: =SUMIF($B$5:$B$16,A22,$K$5:$K$16) -> 9279.36 | C22: =B22/CostingPax -> 21.48
A23: Butter Naan | B23: =SUMIF($B$5:$B$16,A23,$K$5:$K$16) -> 4401.432 | C23: =B23/CostingPax -> 10.1885
A24: Gulab Jamun | B24: =SUMIF($B$5:$B$16,A24,$K$5:$K$16) -> 7820.064 | C24: =B24/CostingPax -> 18.102
A25: TOTAL | B25: =SUM(B21:B24) -> 38171.304

Sheet Coffee Cost
A1: COFFEE COST ESTIMATE
A2: Beverage station consumables and service cost. Total Cost = Quantity x Rate per Unit x No. of Days.
A4: Item Category | B4: Item | C4: Unit | D4: Quantity | E4: Rate per Unit (₹) | F4: No. of Days | G4: Total Cost (₹) | H4: Notes
A5: Beverage | B5: Coffee Beans | C5: kg | D5: 6 | E5: 950 | F5: 2 | G5: =D5*E5*F5 -> 11400
A6: Beverage | B6: Milk | C6: litre | D6: 40 | E6: 62 | F6: 2 | G6: =D6*E6*F6 -> 4960
A7: Beverage | B7: Alternative Milk | C7: litre | D7: 8 | E7: 180 | F7: 2 | G7: =D7*E7*F7 -> 2880
A8: Consumables | B8: Sugar | C8: kg | D8: 5 | E8: 48 | F8: 2 | G8: =D8*E8*F8 -> 480
A9: Consumables | B9: Cups | C9: pcs | D9: 450 | E9: 8 | F9: 2 | G9: =D9*E9*F9 -> 7200
A10: Consumables | B10: Stirrers | C10: pcs | D10: 450 | E10: 1 | F10: 2 | G10: =D10*E10*F10 -> 900
A11: Consumables | B11: Napkins | C11: pcs | D11: 450 | E11: 2 | F11: 2 | G11: =D11*E11*F11 -> 1800
A12: Manpower | B12: Barista | C12: shift | D12: 2 | E12: 2200 | F12: 2 | G12: =D12*E12*F12 -> 8800
A13: Equipment | B13: Coffee Machine Rental | C13: day | D13: 1 | E13: 3500 | F13: 2 | G13: =D13*E13*F13 -> 7000
A14: Consumables | B14: Other Consumables | C14: lot | D14: 1 | E14: 2500 | F14: 2 | G14: =D14*E14*F14 -> 5000
G15: =SUM(G5:G14) -> 50420

Sheet Cocktail Mocktail Bar
A1: COCKTAIL & MOCKTAIL BAR COST
A2: Non-alcoholic bar program costing. Total Cost = Quantity x Rate per Unit x No. of Days. Alcohol is EXCLUDED unless manually added as a line item below.
A4: Category | B4: Item | C4: Unit | D4: Quantity | E4: Rate per Unit (₹) | F4: No. of Days | G4: Total Cost (₹) | H4: Notes
A5: Mixers | B5: Tonic / Soda / Cola Mixers | C5: litre | D5: 25 | E5: 90 | F5: 2 | G5: =D5*E5*F5 -> 4500
A6: Juices | B6: Fresh Juices | C6: litre | D6: 30 | E6: 140 | F6: 2 | G6: =D6*E6*F6 -> 8400
A7: Syrups | B7: Flavoured Syrups | C7: litre | D7: 6 | E7: 450 | F7: 2 | G7: =D7*E7*F7 -> 5400
A8: Garnishes | B8: Cocktail Garnishes | C8: kg | D8: 4 | E8: 200 | F8: 2 | G8: =D8*E8*F8 -> 1600
A9: Herbs | B9: Mint & Herbs | C9: kg | D9: 3 | E9: 180 | F9: 2 | G9: =D9*E9*F9 -> 1080
A10: Fruits | B10: Bar Fruits (Citrus etc.) | C10: kg | D10: 15 | E10: 120 | F10: 2 | G10: =D10*E10*F10 -> 3600
A11: Ice | B11: Ice | C11: kg | D11: 120 | E11: 15 | F11: 2 | G11: =D11*E11*F11 -> 3600
A12: Glassware | B12: Bar Glassware Rental | C12: pcs | D12: 250 | E12: 20 | F12: 2 | G12: =D12*E12*F12 -> 10000
A13: Bar Tools | B13: Bar Tools & Equipment | C13: lot | D13: 1 | E13: 3500 | F13: 2 | G13: =D13*E13*F13 -> 7000
A14: Bartender | B14: Bartender | C14: shift | D14: 4 | E14: 2200 | F14: 2 | G14: =D14*E14*F14 -> 17600
A15: Bar Consumables | B15: Bar Consumables | C15: lot | D15: 1 | E15: 2500 | F15: 2 | G15: =D15*E15*F15 -> 5000
A16: Disposable Items | B16: Disposable Cups / Napkins | C16: pcs | D16: 500 | E16: 6 | F16: 2 | G16: =D16*E16*F16 -> 6000
A17: Other | B17: Miscellaneous Bar Items | C17: lot | D17: 1 | E17: 1500 | F17: 2 | G17: =D17*E17*F17 -> 3000
G18: =SUM(G5:G17) -> 76780
A20: Note: Alcohol (spirits, wine, beer, champagne) is excluded from this costing sheet by default. If the client requires alcohol procurement, add it as a manual line item above with category 'Other'.

Sheet Misc Expenses
A1: MISCELLANEOUS EXPENSES
A2: Event-support costs that don't fall under a specific cost head. Total Cost = Quantity x Unit Rate (set Required = No to exclude a line from totals).
A4: Expense Category | B4: Expense Description | C4: Quantity | D4: Unit Rate (₹) | E4: Total Cost (₹) | F4: Required? | G4: Notes
A5: Printing | B5: Menu Cards & Signage Printing | C5: 1 | D5: 4500 | E5: =IF(F5="No",0,C5*D5) -> 4500 | F5: Yes
A6: Menu Cards | B6: Designer Menu Cards | C6: 420 | D6: 45 | E6: =IF(F6="No",0,C6*D6) -> 18900 | F6: Yes
A7: Collaterals | B7: Branding Collaterals | C7: 1 | D7: 6000 | E7: =IF(F7="No",0,C7*D7) -> 6000 | F7: Yes
A8: Cleaning Material | B8: Cleaning Material & Supplies | C8: 1 | D8: 2500 | E8: =IF(F8="No",0,C8*D8) -> 2500 | F8: Yes
A9: Staff Meals | B9: Staff Meals (Setup Crew) | C9: 25 | D9: 180 | E9: =IF(F9="No",0,C9*D9) -> 4500 | F9: Yes
A10: Packaging | B10: Takeaway / Packaging Material | C10: 1 | D10: 3000 | E10: =IF(F10="No",0,C10*D10) -> 3000 | F10: Yes
A11: Emergency Purchases | B11: Emergency Purchase Buffer | C11: 1 | D11: 5000 | E11: =IF(F11="No",0,C11*D11) -> 5000 | F11: Yes
A12: Petty Cash | B12: Event-Day Petty Cash | C12: 1 | D12: 5000 | E12: =IF(F12="No",0,C12*D12) -> 5000 | F12: Yes
A13: Ice Boxes | B13: Ice Boxes & Coolers | C13: 6 | D13: 350 | E13: =IF(F13="No",0,C13*D13) -> 2100 | F13: Yes
A14: Permissions | B14: Local Permissions / Licenses | C14: 1 | D14: 8000 | E14: =IF(F14="No",0,C14*D14) -> 0 | F14: No
A15: Event-Day Purchases | B15: Event-Day Fuel Top-ups & Sundries | C15: 1 | D15: 3000 | E15: =IF(F15="No",0,C15*D15) -> 3000 | F15: Yes
E16: =SUM(E5:E15) -> 54500

Sheet ODC Chef Cost
A1: ODC CHEF COST (OFF-SITE / OUTDOOR CATERING)
A2: Culinary team deployed to site. Total Cost = (No. of Chefs x Shifts x Rate per Shift) + Travel Allowance + Meal Cost + Accommodation Cost.
A4: Chef Role | B4: No. of Chefs | C4: No. of Shifts / Days | D4: Rate per Shift (₹) | E4: Travel Allowance (₹) | F4: Meal Cost (₹) | G4: Accommodation Cost (₹) | H4: Total Cost (₹) | I4: Notes
A5: Head Chef | B5: 1 | C5: 2 | D5: 6000 | E5: 2000 | F5: 400 | G5: 4000 | H5: =B5*C5*D5+E5+F5+G5 -> 18400
A6: Sous Chef | B6: 1 | C6: 2 | D6: 4000 | E6: 1500 | F6: 400 | G6: 3000 | H6: =B6*C6*D6+E6+F6+G6 -> 12900
A7: CDP | B7: 2 | C7: 2 | D7: 3200 | E7: 1000 | F7: 400 | G7: 2500 | H7: =B7*C7*D7+E7+F7+G7 -> 16700
A8: Commis | B8: 4 | C8: 2 | D8: 1600 | E8: 500 | F8: 400 | G8: 0 | H8: =B8*C8*D8+E8+F8+G8 -> 13700
A9: Live Station Chef | B9: 3 | C9: 2 | D9: 2800 | E9: 800 | F9: 400 | G9: 0 | H9: =B9*C9*D9+E9+F9+G9 -> 18000
A10: Dessert Chef | B10: 1 | C10: 2 | D10: 2800 | E10: 800 | F10: 400 | G10: 0 | H10: =B10*C10*D10+E10+F10+G10 -> 6800
A11: Bakery Chef | B11: 1 | C11: 2 | D11: 2800 | E11: 800 | F11: 400 | G11: 0 | H11: =B11*C11*D11+E11+F11+G11 -> 6800
A12: Indian Chef | B12: 2 | C12: 2 | D12: 2600 | E12: 600 | F12: 400 | G12: 0 | H12: =B12*C12*D12+E12+F12+G12 -> 11400
A13: Continental Chef | B13: 1 | C13: 2 | D13: 2800 | E13: 600 | F13: 400 | G13: 0 | H13: =B13*C13*D13+E13+F13+G13 -> 6600
A14: Asian Chef | B14: 1 | C14: 2 | D14: 2800 | E14: 600 | F14: 400 | G14: 0 | H14: =B14*C14*D14+E14+F14+G14 -> 6600
A15: TOTAL ODC CHEF COST | H15: =SUM(H5:H14) -> 117900

Sheet Transportation
A1: TRANSPORTATION COST
A2: Vehicles, fuel and logistics manpower. Total Cost = (Vehicles x Trips x Rate per Trip) + Fuel/Toll/Parking + Driver Charges + Loading/Unloading + Night Charges.
A4: Vehicle Type | B4: Purpose | C4: No. of Vehicles | D4: No. of Trips | E4: Rate per Trip (₹) | F4: Fuel / Toll / Parking (₹) | G4: Driver Charges (₹) | H4: Loading / Unloading Cost (₹) | I4: Night Charges (₹) | J4: Total Cost (₹) | K4: Notes
A5: Small Tempo | B5: Crockery & setup material transport | C5: 2 | D5: 2 | E5: 2500 | F5: 1200 | G5: 1000 | H5: 800 | I5: 500 | J5: =C5*D5*E5+F5+G5+H5+I5 -> 13500
A6: Large Tempo | B6: Buffet counters & furniture transport | C6: 1 | D6: 2 | E6: 4500 | F6: 1800 | G6: 1200 | H6: 1200 | I6: 800 | J6: =C6*D6*E6+F6+G6+H6+I6 -> 14000
A7: Refrigerated Vehicle | B7: Perishable food transport | C7: 1 | D7: 2 | E7: 6000 | F7: 2000 | G7: 1500 | H7: 800 | I7: 800 | J7: =C7*D7*E7+F7+G7+H7+I7 -> 17100
A8: Car | B8: Chef / supervisor movement | C8: 2 | D8: 2 | E8: 1800 | F8: 800 | G8: 900 | H8: 0 | I8: 0 | J8: =C8*D8*E8+F8+G8+H8+I8 -> 8900
A9: Pickup Vehicle | B9: Last-mile / emergency runs | C9: 1 | D9: 3 | E9: 1500 | F9: 900 | G9: 800 | H9: 500 | I9: 500 | J9: =C9*D9*E9+F9+G9+H9+I9 -> 7200
A10: SUBTOTAL | J10: =SUM(J5:J9) -> 60700
A11: Transportation Contingency | J11: =J10*TransportContingencyPct -> 3035
A12: TOTAL TRANSPORTATION COST | J12: =J10+J11 -> 63735

Sheet Actual Cost Entry
A1: ACTUAL COST ENTRY
A2: Populate this sheet after the project is executed. Enter one row per vendor payment / invoice. Cost Head must match the estimate sheets for accurate variance analysis.
A4: Date | B4: Vendor / Payee | C4: Invoice No. | D4: Cost Head | E4: Subcategory | F4: Description | G4: Estimated Amount (₹) | H4: Actual Amount (₹) | I4: Payment Status | J4: Paid By | K4: Mode of Payment | L4: Remarks
A5: 2026-11-10 | B5: Elite Rentals | C5: INV-1042 | D5: Setup | E5: Crockery & Cutlery | F5: Crockery/cutlery/glassware rental | G5: 45000 | H5: 46200 | I5: Paid | J5: Accounts | K5: Bank Transfer
A6: 2026-11-11 | B6: Fresh Farm Suppliers | C6: INV-2231 | D6: Food | E6: Vegetables & Dairy | F6: Fresh produce & dairy procurement | G6: 180000 | H6: 176500 | I6: Paid | J6: Accounts | K6: UPI
A7: 2026-11-12 | B7: In-house Payroll | C7: PAYROLL-114 | D7: Service | E7: Service Staff Wages | F7: Service team wages for 2 days | G7: 220000 | H7: 228000 | I7: Paid | J7: HR | K7: Bank Transfer
A8: 2026-11-13 | B8: City Logistics | C8: INV-887 | D8: Transportation | E8: Tempo & Refrigerated Van | F8: Transport of setup and food material | G8: 32000 | H8: 33500 | I8: Paid | J8: Accounts | K8: Cash
A9: 2026-11-14 | B9: Bean & Brew Co. | C9: INV-556 | D9: Coffee | E9: Coffee Station Consumables | F9: Coffee beans, milk, barista service | G9: 15000 | H9: 14200 | I9: Paid | J9: Accounts | K9: UPI

Sheet Estimate vs Actual
A1: ESTIMATE VS ACTUAL
A2: Post-event performance review. Status: Under Budget (<-5%), On Budget (-5% to +5%), Over Budget (>+5%).
B4: Cost Head | C4: Estimated Cost (₹) | D4: Actual Cost (₹) | E4: Variance Amount (₹) | F4: Variance % | G4: Status | H4: Remarks
B5: Service | C5: =ServiceCostTotal -> 117820 | D5: =SUMIF('Actual Cost Entry'!$D:$D,B5,'Actual Cost Entry'!$H:$H) -> 228000 | E5: =D5-C5 -> 110180 | F5: =IF(C5=0,0,E5/C5) -> 0.93515532 | G5: =IF(F5<-0.05,"Under Budget",IF(F5<=0.05,"On Budget","Over Budget")) -> Over Budget
B6: Setup | C6: =SetupCostTotal -> 225378 | D6: =SUMIF('Actual Cost Entry'!$D:$D,B6,'Actual Cost Entry'!$H:$H) -> 46200 | E6: =D6-C6 -> -179178 | F6: =IF(C6=0,0,E6/C6) -> -0.79501105 | G6: =IF(F6<-0.05,"Under Budget",IF(F6<=0.05,"On Budget","Over Budget")) -> Under Budget
B7: Food | C7: =FoodCostTotal -> 38171.304 | D7: =SUMIF('Actual Cost Entry'!$D:$D,B7,'Actual Cost Entry'!$H:$H) -> 176500 | E7: =D7-C7 -> 138328.7 | F7: =IF(C7=0,0,E7/C7) -> 3.6238923 | G7: =IF(F7<-0.05,"Under Budget",IF(F7<=0.05,"On Budget","Over Budget")) -> Over Budget
B8: Coffee | C8: =CoffeeCostTotal -> 50420 | D8: =SUMIF('Actual Cost Entry'!$D:$D,B8,'Actual Cost Entry'!$H:$H) -> 14200 | E8: =D8-C8 -> -36220 | F8: =IF(C8=0,0,E8/C8) -> -0.71836573 | G8: =IF(F8<-0.05,"Under Budget",IF(F8<=0.05,"On Budget","Over Budget")) -> Under Budget
B9: Cocktail & Mocktail Bar | C9: =BarCostTotal -> 76780 | D9: =SUMIF('Actual Cost Entry'!$D:$D,B9,'Actual Cost Entry'!$H:$H) -> 0 | E9: =D9-C9 -> -76780 | F9: =IF(C9=0,0,E9/C9) -> -1 | G9: =IF(F9<-0.05,"Under Budget",IF(F9<=0.05,"On Budget","Over Budget")) -> Under Budget
B10: Miscellaneous Expenses | C10: =MiscCostTotal -> 54500 | D10: =SUMIF('Actual Cost Entry'!$D:$D,B10,'Actual Cost Entry'!$H:$H) -> 0 | E10: =D10-C10 -> -54500 | F10: =IF(C10=0,0,E10/C10) -> -1 | G10: =IF(F10<-0.05,"Under Budget",IF(F10<=0.05,"On Budget","Over Budget")) -> Under Budget
B11: ODC Chef Cost | C11: =ChefCostTotal -> 117900 | D11: =SUMIF('Actual Cost Entry'!$D:$D,B11,'Actual Cost Entry'!$H:$H) -> 0 | E11: =D11-C11 -> -117900 | F11: =IF(C11=0,0,E11/C11) -> -1 | G11: =IF(F11<-0.05,"Under Budget",IF(F11<=0.05,"On Budget","Over Budget")) -> Under Budget
B12: Transportation | C12: =TransportCostTotal -> 63735 | D12: =SUMIF('Actual Cost Entry'!$D:$D,B12,'Actual Cost Entry'!$H:$H) -> 33500 | E12: =D12-C12 -> -30235 | F12: =IF(C12=0,0,E12/C12) -> -0.47438613 | G12: =IF(F12<-0.05,"Under Budget",IF(F12<=0.05,"On Budget","Over Budget")) -> Under Budget
A14: OVERALL PROJECT PERFORMANCE
B15: Total Estimated Cost | C15: =SUM(C5:C12) -> 744704.3
B16: Total Actual Cost | C16: =SUM(D5:D12) -> 498400
B17: Total Variance | C17: =C16-C15 -> -246304.3
B18: Overall Variance % | C18: =IF(C15=0,0,C17/C15) -> -0.33074108
B19: Final Project Marking | C19: =IF(C18<=-0.05,"Excellent",IF(C18<=0.05,"Good","Poor")) -> Excellent

Sheet Rate Master
A1: RATE MASTER
A2: Central rate library for the costing team. Rates in the cost sheets can be manually cross-checked against or linked to this master over time.
A4: STAFF ROLE RATES
A5: Category | B5: Item | C5: Unit | D5: Standard Rate (₹) | E5: Preferred Vendor | F5: Last Updated | G5: Notes
A6: Service | B6: Service Captain | C6: per shift | D6: 2500 | E6: In-house | F6: 2026-07-01 | G6: 8-hour shift
A7: Service | B7: Butler | C7: per shift | D7: 2200 | E7: In-house | F7: 2026-07-01
A8: Service | B8: Server | C8: per shift | D8: 1200 | E8: In-house | F8: 2026-07-01
A9: Service | B9: Support Staff | C9: per shift | D9: 1000 | E9: In-house | F9: 2026-07-01
A10: Service | B10: Steward | C10: per shift | D10: 1100 | E10: In-house | F10: 2026-07-01
A11: Service | B11: Housekeeping | C11: per shift | D11: 1000 | E11: In-house | F11: 2026-07-01
A13: CHEF ROLE RATES
A14: Category | B14: Item | C14: Unit | D14: Standard Rate (₹) | E14: Preferred Vendor | F14: Last Updated | G14: Notes
A15: Chef | B15: Head Chef | C15: per shift | D15: 6000 | E15: In-house | F15: 2026-07-01
A16: Chef | B16: Sous Chef | C16: per shift | D16: 4000 | E16: In-house | F16: 2026-07-01
A17: Chef | B17: CDP | C17: per shift | D17: 3200 | E17: In-house | F17: 2026-07-01
A18: Chef | B18: Commis | C18: per shift | D18: 1600 | E18: In-house | F18: 2026-07-01
A19: Chef | B19: Live Station Chef | C19: per shift | D19: 2800 | E19: In-house | F19: 2026-07-01
A21: CROCKERY & CUTLERY RATES
A22: Category | B22: Item | C22: Unit | D22: Standard Rate (₹) | E22: Preferred Vendor | F22: Last Updated | G22: Notes
A23: Crockery | B23: Crockery Set | C23: per cover/day | D23: 45 | E23: Elite Rentals | F23: 2026-07-01
A24: Cutlery | B24: Cutlery Set | C24: per cover/day | D24: 20 | E24: Elite Rentals | F24: 2026-07-01
A25: Glassware | B25: Glassware Set | C25: per cover/day | D25: 25 | E25: Elite Rentals | F25: 2026-07-01
A26: Chafing Dishes | B26: Chafing Dish | C26: per unit/day | D26: 350 | E26: Elite Rentals | F26: 2026-07-01
A28: FOOD INGREDIENT RATES
A29: Category | B29: Item | C29: Unit | D29: Standard Rate (₹) | E29: Preferred Vendor | F29: Last Updated | G29: Notes
A30: Dairy | B30: Paneer | C30: kg | D30: 380 | E30: Fresh Farm Suppliers | F30: 2026-07-01
A31: Dairy | B31: Butter & Cream | C31: kg | D31: 450 | E31: Fresh Farm Suppliers | F31: 2026-07-01
A32: Dry Stock | B32: Black Lentils (Urad Dal) | C32: kg | D32: 180 | E32: Grain Traders Co. | F32: 2026-07-01
A33: Dry Stock | B33: Sugar | C33: kg | D33: 55 | E33: Grain Traders Co. | F33: 2026-07-01
A34: Bakery | B34: Refined Flour (Maida) | C34: kg | D34: 45 | E34: City Bakery Supplies | F34: 2026-07-01
A35: Vegetables | B35: Mixed Vegetables | C35: kg | D35: 60 | E35: Fresh Farm Suppliers | F35: 2026-07-01
A37: COFFEE ITEM RATES
A38: Category | B38: Item | C38: Unit | D38: Standard Rate (₹) | E38: Preferred Vendor | F38: Last Updated | G38: Notes
A39: Beverage | B39: Coffee Beans | C39: kg | D39: 950 | E39: Bean & Brew Co. | F39: 2026-07-01
A40: Beverage | B40: Milk | C40: litre | D40: 62 | E40: Fresh Farm Suppliers | F40: 2026-07-01
A41: Equipment | B41: Coffee Machine Rental | C41: per day | D41: 3500 | E41: Bean & Brew Co. | F41: 2026-07-01
A42: Manpower | B42: Barista | C42: per shift | D42: 2200 | E42: Bean & Brew Co. | F42: 2026-07-01
A44: BAR ITEM RATES
A45: Category | B45: Item | C45: Unit | D45: Standard Rate (₹) | E45: Preferred Vendor | F45: Last Updated | G45: Notes
A46: Juices | B46: Fresh Juices | C46: litre | D46: 140 | E46: Fresh Farm Suppliers | F46: 2026-07-01
...

Sheet Dashboard
A1: EXECUTIVE DASHBOARD
A2: Live snapshot of project economics — pulled automatically from the estimate, commercial and actuals sheets.
B4: PROJECT NAME | F4: ESTIMATED PAX | J4: COSTING PAX | N4: TOTAL ESTIMATED BASE COST
B5: =ProjectName_ -> The Grand Wedding Weekend | F5: =EstimatedPax -> 400 | J5: =CostingPax -> 432 | N5: =TotalEstimatedBaseCost -> 767045.43
B7: ESTIMATED COST PER PAX | F7: FINAL COMMERCIAL (BEFORE GST) | J7: FINAL COMMERCIAL (INCL. GST) | N7: TOTAL ACTUAL COST
B8: =EstimatedCostPerPax -> 1775.5681 | F8: =FinalCommercialBeforeGST -> 920454.52 | J8: =FinalCommercialInclGST -> 1086136.3 | N8: =TotalActualCost -> 498400
B10: ACTUAL COST PER PAX | F10: OVERALL VARIANCE % | J10: FINAL PROJECT MARKING
B11: =IF(CostingPax=0,0,TotalActualCost/CostingPax) -> 1153.7037 | F11: =OverallVariancePct -> -0.33074108 | J11: =FinalProjectMarking -> Excellent
A14: COST HEAD BREAKDOWN (CHART SOURCE)
B15: Cost Head | C15: Estimated Cost (₹) | D15: Actual Cost (₹) | E15: % Contribution
B16: Service | C16: ='Estimate vs Actual'!C5 -> 117820 | D16: ='Estimate vs Actual'!D5 -> 228000 | E16: =C16/TotalEstimatedBaseCost -> 0.15360237
B17: Setup | C17: ='Estimate vs Actual'!C6 -> 225378 | D17: ='Estimate vs Actual'!D6 -> 46200 | E17: =C17/TotalEstimatedBaseCost -> 0.29382614
B18: Food | C18: ='Estimate vs Actual'!C7 -> 38171.304 | D18: ='Estimate vs Actual'!D7 -> 176500 | E18: =C18/TotalEstimatedBaseCost -> 0.049764072
B19: Coffee | C19: ='Estimate vs Actual'!C8 -> 50420 | D19: ='Estimate vs Actual'!D8 -> 14200 | E19: =C19/TotalEstimatedBaseCost -> 0.065732743
B20: Cocktail & Mocktail Bar | C20: ='Estimate vs Actual'!C9 -> 76780 | D20: ='Estimate vs Actual'!D9 -> 0 | E20: =C20/TotalEstimatedBaseCost -> 0.10009837
B21: Miscellaneous Expenses | C21: ='Estimate vs Actual'!C10 -> 54500 | D21: ='Estimate vs Actual'!D10 -> 0 | E21: =C21/TotalEstimatedBaseCost -> 0.071051854
B22: ODC Chef Cost | C22: ='Estimate vs Actual'!C11 -> 117900 | D22: ='Estimate vs Actual'!D11 -> 0 | E22: =C22/TotalEstimatedBaseCost -> 0.15370667
B23: Transportation | C23: ='Estimate vs Actual'!C12 -> 63735 | D23: ='Estimate vs Actual'!D12 -> 33500 | E23: =C23/TotalEstimatedBaseCost -> 0.083091558

Sheet Instructions
A1: HOW TO USE THIS WORKBOOK
A2: Catering Project Cost Estimator — internal costing & operations model.
A4: 1. WORKFLOW ORDER
B5: Work through the workbook in this order: Project Inputs -> the 8 cost head sheets -> Estimate Summary -> (load profit) -> run the event -> Actual Cost Entry -> Estimate vs Actual -> Dashboard for review.
A7: 2. FILLING PROJECT INPUTS
B8: Start here for every new project. Enter Project Name, Client, Event Date, Venue, Pax and dates.
B9: Estimated Pax is the client-confirmed guest count. Buffer % is a safety margin (5-10% typical); Costing Pax is auto-calculated and is what every cost sheet uses to size quantities.
B10: Global Assumptions (Wastage %, Contingency %, GST %, Staff Meal Cost, shift rates) are used across every cost sheet, so review them for each new project before entering line items.
A12: 3. ENTERING ESTIMATES IN THE COST SHEETS
B13: Service Cost, Setup Cost, Coffee Cost, Cocktail & Mocktail Bar, Misc Expenses, ODC Chef Cost and Transportation each list sample roles/items with editable quantities and rates (cream/blue cells).
B14: Food Cost works at ingredient level: add one row per ingredient per dish, tagged to a Menu Section and Dish Name. The Dish-Wise Summary block below the main table rolls each dish up automatically.
B15: Add more rows inside any table by inserting a row within the existing table range — formulas and formatting will extend automatically. Grand totals use SUM over the table column, so new rows are included.
A17: 4. USING THE RATE MASTER
B18: Rate Master is the central price list (staff, chef, crockery, food, coffee, bar, transport, misc). Use it as the reference when entering 'Rate' values in the cost sheets so pricing stays consistent across projects. Update 'Last Updated' whenever a rate changes with a vendor.
A20: 5. LOADING PROFIT
B21: Profit is loaded only on the Estimate Summary sheet, in the 'Commercial View' block below the base cost.
B22: Enter Profit Loading % (editable). Profit Amount, Final Commercial Before GST, GST Amount and Final Commercial Including GST all calculate automatically. The Total Estimated Base Cost above this block never includes profit — it stays a pure cost figure for internal review.
A24: 6. ENTERING ACTUAL COSTS (AFTER THE EVENT)
B25: Once the project is executed, log every vendor payment/invoice as one row in Actual Cost Entry.
B26: Cost Head must be chosen from the dropdown and must match one of the 8 estimate cost heads exactly, otherwise that spend will not roll up correctly in Estimate vs Actual.
A28: 7. READING ESTIMATE VS ACTUAL
B29: This sheet compares Estimated Cost (from the estimate sheets) against Actual Cost (summed from Actual Cost Entry) per cost head, showing Variance Amount, Variance % and a Status flag.
B30: Status / colour coding: Under Budget = green (more than 5% below estimate), On Budget = yellow (within +/-5%), Over Budget = red (more than 5% above estimate).
B31: The bottom section gives Total Estimated Cost, Total Actual Cost, Total Variance, Overall Variance % and a Final Project Marking: Excellent (>=5% under), Good (within estimate to +5% over), Poor (>5% over).
A33: 8. EDITABLE VS FORMULA CELLS
B34: Cream/yellow-filled cells with blue text are editable inputs — quantities, rates, dates, names, dropdowns.
B35: White cells with black text are formulas and are locked; sheets are protected so these cannot be accidentally overwritten, while input cells remain fully editable.
B36: Green italic text marks a value linked in from another sheet (e.g. cost head totals on Estimate Summary) — edit the source sheet, not the link.
A38: 9. DASHBOARD
B39: The Dashboard sheet is a read-only, management-facing view: key KPIs and three charts (Estimated Cost by Cost Head, Estimate vs Actual by Cost Head, Cost Head % Contribution). Nothing needs to be entered here.

Sheet Lists
A1: YesNo | B1: EventType | C1: MenuType | D1: ServiceStyle | E1: IngredientCategory | F1: CostHead | G1: PaymentStatus | H1: ModeOfPayment | I1: RoleCategory
A2: Yes | B2: Wedding | C2: Pure Veg | D2: Buffet | E2: Dry Stock | F2: Service | G2: Paid | H2: Cash | I2: Front of House
A3: No | B3: Corporate Event | C3: Veg + Non-Veg | D3: Plated / Sit-Down | E3: Vegetables | F3: Setup | G3: Pending | H3: Bank Transfer | I3: Support
B4: Brand Activation | C4: Non-Veg Only | D4: Live Counters | E4: Fruits | F4: Food | G4: Partial | H4: Cheque | I4: Logistics
B5: Private Party | C5: Jain | D5: Family Style | E5: Dairy | F5: Coffee | G5: Advance Paid | H5: Credit Card | I5: Housekeeping
B6: Social Gathering | C6: Custom / Mixed | D6: Cocktail / Standing | E6: Bakery | F6: Cocktail & Mocktail Bar | H6: UPI | I6: Management
B7: Exhibition / Launch | D7: Mixed Service | E7: Poultry | F7: Miscellaneous Expenses | H7: Vendor Credit
B8: Other | E8: Meat | F8: ODC Chef Cost
E9: Seafood | F9: Transportation
E10: Spices
E11: Condiments
E12: Sauces
E13: Oils
E14: Garnish
E15: Packaging
E16: Other
